Genearte group analysis
	Started: 17-02-07 21:29:44
	RunTime: 2.0

Statistycal analysis of the groups
	Started: 17-02-07 21:29:46
/usr/lib/python2.7/dist-packages/scipy/stats/stats.py:3312: RuntimeWarning: invalid value encountered in divide
  t = np.divide(d, denom)
/usr/lib/python2.7/dist-packages/scipy/stats/distributions.py:1417: RuntimeWarning: invalid value encountered in greater
  cond1 = (scale > 0) & (x > self.a) & (x < self.b)
/usr/lib/python2.7/dist-packages/scipy/stats/distributions.py:1417: RuntimeWarning: invalid value encountered in less
  cond1 = (scale > 0) & (x > self.a) & (x < self.b)
/usr/lib/python2.7/dist-packages/scipy/stats/distributions.py:1418: RuntimeWarning: invalid value encountered in less_equal
  cond2 = cond0 & (x <= self.a)
	RunTime: 5.0

Outlier analysis
	Started: 17-02-07 21:29:51
/home/anton/HaSAPPy/program/GroupAnalysis.py:268: RuntimeWarning: divide by zero encountered in log10
  outlier_mean = np.log10(outlier_mean)
/usr/lib/pymodules/python2.7/matplotlib/collections.py:548: FutureWarning: elementwise comparison failed; returning scalar instead, but in the future will perform elementwise comparison
  if self._edgecolors == 'face':
/usr/lib/pymodules/python2.7/mpl_toolkits/mplot3d/axes3d.py:1088: FutureWarning: comparison to `None` will result in an elementwise object comparison in the future.
  if self.button_pressed in self._rotate_btn:
	RunTime: 1391.0

Columns: 
	Control_II_ctrl4 | Control_II_ctrl5 | Control_II_ctrl6 | Control_II_ctrl7 | Control_II_ctrl1 | Control_II_ctrl2 | Control_II_ctrl3 | Control_II_mean | Control_II_stdev | Selected_II_sel4 | Selected_II_sel5 | Selected_II_sel6 | Selected_II_sel7 | Selected_II_sel1 | Selected_II_sel2 | Selected_II_sel3 | Selected_II_mean | Selected_II_stdev | Selected_II_fold | Selected_II_ttest | Control_KI_ctrl4 | Control_KI_ctrl5 | Control_KI_ctrl6 | Control_KI_ctrl7 | Control_KI_ctrl1 | Control_KI_ctrl2 | Control_KI_ctrl3 | Control_KI_mean | Control_KI_stdev | Selected_KI_sel4 | Selected_KI_sel5 | Selected_KI_sel6 | Selected_KI_sel7 | Selected_KI_sel1 | Selected_KI_sel2 | Selected_KI_sel3 | Selected_KI_mean | Selected_KI_stdev | Selected_KI_fold | Selected_KI_ttest | Control_Bias_ctrl4 | Control_Bias_ctrl5 | Control_Bias_ctrl6 | Control_Bias_ctrl7 | Control_Bias_ctrl1 | Control_Bias_ctrl2 | Control_Bias_ctrl3 | Control_Bias_mean | Control_Bias_stdev | Selected_Bias_sel4 | Selected_Bias_sel5 | Selected_Bias_sel6 | Selected_Bias_sel7 | Selected_Bias_sel1 | Selected_Bias_sel2 | Selected_Bias_sel3 | Selected_Bias_mean | Selected_Bias_stdev | Selected_Bias_fold | Selected_Bias_ttest | Control_Reads_ctrl4 | Control_Reads_ctrl5 | Control_Reads_ctrl6 | Control_Reads_ctrl7 | Control_Reads_ctrl1 | Control_Reads_ctrl2 | Control_Reads_ctrl3 | Control_Reads_mean | Control_Reads_stdev | Selected_Reads_sel4 | Selected_Reads_sel5 | Selected_Reads_sel6 | Selected_Reads_sel7 | Selected_Reads_sel1 | Selected_Reads_sel2 | Selected_Reads_sel3 | Selected_Reads_mean | Selected_Reads_stdev | Selected_Reads_fold | Selected_Reads_ttest | Selected_Score

Saved RowData analysis in : /media/HDD/analysis/Analysis/2017-02-07/row/RowData.pkl
Saved GroupAnalysis file (necessary for table generation) in : /media/HDD/analysis/Analysis/2017-02-07/row/GroupAnalysis.pkl
Writing in Input Info files their usage for this analysis
***	END Perform Group Analysis	***
Traceback (most recent call last):
  File "HaSAPPY_start.py", line 48, in <module>
    Tables.main(analysis)
  File "/home/anton/HaSAPPy/program/Tables.py", line 128, in main
    tables.append(create_table(Info,GroupAnalysis,summary,keys,filters,table))
  File "/home/anton/HaSAPPy/program/Tables.py", line 111, in create_table
    table[name] = summary[name]
  File "/usr/local/lib/python2.7/dist-packages/pandas/core/frame.py", line 2059, in __getitem__
    return self._getitem_column(key)
  File "/usr/local/lib/python2.7/dist-packages/pandas/core/frame.py", line 2066, in _getitem_column
    return self._get_item_cache(key)
  File "/usr/local/lib/python2.7/dist-packages/pandas/core/generic.py", line 1386, in _get_item_cache
    values = self._data.get(item)
  File "/usr/local/lib/python2.7/dist-packages/pandas/core/internals.py", line 3543, in get
    loc = self.items.get_loc(item)
  File "/usr/local/lib/python2.7/dist-packages/pandas/indexes/base.py", line 2136, in get_loc
    return self._engine.get_loc(self._maybe_cast_indexer(key))
  File "pandas/index.pyx", line 132, in pandas.index.IndexEngine.get_loc (pandas/index.c:4145)
  File "pandas/index.pyx", line 154, in pandas.index.IndexEngine.get_loc (pandas/index.c:4009)
  File "pandas/src/hashtable_class_helper.pxi", line 732, in pandas.hashtable.PyObjectHashTable.get_item (pandas/hashtable.c:13166)
  File "pandas/src/hashtable_class_helper.pxi", line 740, in pandas.hashtable.PyObjectHashTable.get_item (pandas/hashtable.c:13120)
KeyError: 'Control_II_row'

